<?xml version="1.0" encoding="utf-8"?>
<!-- SEE: http://wiki.ros.org/urdf/XML for a description of the format
	 SEE: https://github.com/poppy-project/poppy-humanoid/blob/master/hardware/URDF/robots/Poppy_Humanoid.URDF for parameter details
	- rpy means roll, pitch, yaw 
   	- lengths ~ m -->
<robot name="bert">
	<link name="PELVIS"/>
	<link name="RIGHT_HIP_SOCKET"/>
	<link name="RIGHT_HIP_LINK"/>
	<link name="RIGHT_THIGH"/>
	<link name="RIGHT_SHIN"/>
	<link name="RIGHT_FOOT"/>
	<link name="LEFT_HIP_SOCKET"/>
	<link name="LEFT_HIP_LINK"/>
	<link name="LEFT_THIGH"/>
	<link name="LEFT_SHIN"/>
	<link name="LEFT_FOOT"/>
	<link name="LUMBAR"/>
	<link name="LOWER_SPINE"/>
	<link name="SPINE"/>
	<link name="THORACIC"/>
	<link name="BACK"/>
	<link name="CERVICAL"/>
	<link name="HEAD">
		<appendage name="left eye"/>
		<appendage name="right eye"/>
		<appendage name="left ear"/>
		<appendage name="right ear"/>
		<appendage name="nose"/>
	</link>
	<link name="LEFT_CLAVICLE"/>
	<link name="LEFT_SHOULDER_LINK"/>
	<link name="LEFT_UPPER_ARM"/>
	<link name="LEFT_FOREARM"/>
	<link name="RIGHT_CLAVICLE"/>
	<link name="RIGHT_SHOULDER_LINK"/>
	<link name="RIGHT_UPPER_ARM"/>
	<link name="RIGHT_FOREARM"/>>
	<!-- Joint names must match the names in bert.xml -->
	<joint name="RIGHT_HIP_X" type="revolute">
		<origin xyz="-0.0225417390633467 0 0" rpy="1.5707963267949 0 0"></origin>
		<parent link="PELVIS"></parent>
		<child link="RIGHT_HIP_SOCKET"></child>
		<axis xyz="0 0 -1"></axis>
	</joint>
	<joint name="RIGHT_HIP_Z" type="revolute">
		<origin xyz="-0.0439986111539757 0 0.005" rpy="0 0 0"></origin>
		<parent link="RIGHT_HIP_SOCKET"></parent>
		<child link="RIGHT_HIP_LINK"></child>
		<axis xyz="0 -1 0"></axis>
	</joint>
	<joint name="RIGHT_HIP_Y" type="revolute">
		<origin xyz="0 -0.024 0" rpy="0 0 0"></origin>
		<parent link="RIGHT_HIP_LINK"></parent>
		<child link="RIGHT_THIGH"></child>
		<axis xyz="-1 0 0"></axis>
	</joint>
	<joint name="RIGHT_KNEE_Y" type="revolute">
		<origin xyz="0 -0.182 0" rpy="0 1.5707963267949 0"></origin>
		<parent link="RIGHT_THIGH"></parent>
		<child link="RIGHT_SHIN"></child>
		<axis xyz="0 0 -1"></axis>
	</joint>
	<joint name="RIGHT_ANKLE_Y" type="revolute">
		<origin xyz="0 -0.18 0" rpy="0 -1.5708 0"></origin>
		<parent link="RIGHT_SHIN"></parent>
		<child link="RIGHT_FOOT"></child>
		<axis xyz="-1 0 0"></axis>
	</joint>
	<joint name="LEFT_HIP_X" type="revolute">
		<origin xyz="0.0225417390633466 0 0" rpy="1.5707963267949 0 0"></origin>
		<parent link="PELVIS"></parent>
		<child link="LEFT_HIP_SOCKET"></child>
		<axis xyz="0 0 -1"></axis>
	</joint>
	<joint name="LEFT_HIP_Z" type="revolute">
		<origin xyz="0.0439986111539757 0 0.005" rpy="0 0 0"></origin>
		<parent link="LEFT_HIP_SOCKET"></parent>
		<child link="LEFT_HIP_LINK"></child>
		<axis xyz="0 -1 0"></axis>
	</joint>
	<joint name="LEFT_HIP_Y" type="revolute">
		<origin xyz="0 -0.024 0" rpy="0 0 0"></origin>
		<parent link="LEFT_HIP_LINK"></parent>
		<child link="LEFT_THIGH"></child>
		<axis xyz="1 0 0"></axis>
	</joint>
	<joint name="LEFT_KNEE_Y" type="revolute">
		<origin xyz="0 -0.182 0" rpy="0 1.5707963267949 0"></origin>
		<parent link="LEFT_THIGH"></parent>
		<child link="LEFT_SHIN"></child>
		<axis xyz="0 0 -1"></axis>
	</joint>
	<joint name="LEFT_ANKLE_Y" type="revolute">
		<origin xyz="0 -0.18 0" rpy="0 -1.5708 0"></origin>
		<parent link="LEFT_SHIN"></parent>
		<child link="LEFT_FOOT"></child>
		<axis xyz="1 0 0"></axis>
	</joint>
	<joint name="ABS_Y" type="revolute">
		<origin xyz="0 -0.017 0.061" rpy="1.5707963267949 0 0"></origin>
		<parent link="PELVIS"></parent>
		<child link="LUMBAR"></child>
		<axis xyz="-1 0 0"></axis>
	</joint>
	<joint name="ABS_X" type="revolute">
		<origin xyz="0 0 0" rpy="0 0 0"></origin>
		<parent link="LUMBAR"></parent>
		<child link="LOWER_SPINE"></child>
		<axis xyz="0 0 1"></axis>
	</joint>
	<joint name="ABS_Z" type="revolute">
		<origin xyz="0 0.0516374742048976 0" rpy="0 0 0"></origin>
		<parent link="LOWER_SPINE"></parent>
		<child link="SPINE"></child>
		<axis xyz="0 1 0"></axis>
	</joint>
	<joint name="BUST_Y" type="revolute">
		<origin xyz="0 0.07985 0.0028" rpy="0 0 0"></origin>
		<parent link="SPINE"></parent>
		<child link="THORACIC"></child>
		<axis xyz="-1 0 0"></axis>
	</joint>
	<joint name="BUST_X" type="revolute">
		<origin xyz="0 0 0" rpy="0 0 0"></origin>
		<parent link="THORACIC"></parent>
		<child link="BACK"></child>
		<axis xyz="0 0 1"></axis>
	</joint>
	<joint name="HEAD_Z" type="revolute">
		<origin xyz="0 0.084 0.005" rpy="0 0 0"></origin>
		<parent link="BACK"></parent>
		<child link="CERVICAL"></child>
		<axis xyz="0 1 0"></axis>
	</joint>
	<joint name="HEAD_Y" type="revolute">
		<origin xyz="0 0.02 0" rpy="-0.349065850398866 0 0"></origin>
		<parent link="CERVICAL"></parent>
		<child link="HEAD"></child>
		<axis xyz="-1 0 0"></axis>
	</joint>
	<joint name="LEFT_SHOULDER_Y" type="revolute">
		<origin xyz="0.0771 0.05 0.004" rpy="-1.5707963267949 0 0"></origin>
		<parent link="BACK"></parent>
		<child link="LEFT_CLAVICLE"></child>
		<axis xyz="1 0 0"></axis>
	</joint>
	<joint name="LEFT_SHOULDER_X" type="revolute">
		<origin xyz="0.0284 0 0" rpy="3.14159265358979 0 1.5707963267949"></origin>
		<parent link="LEFT_CLAVICLE"></parent>
		<child link="LEFT_SHOULDER_LINK"></child>
		<axis xyz="0 0 1"></axis>
	</joint>
	<joint name="LEFT_ARM_Z" type="revolute">
		<origin xyz="0 0.03625 0.0185" rpy="0 0 0"></origin>
		<parent link="LEFT_SHOULDER_LINK"></parent>
		<child link="LEFT_UPPER_ARM"></child>
		<axis xyz="0 1 0"></axis>
	</joint>
	<joint name="LEFT_ELBOW_Y" type="revolute">
		<origin xyz="0 0.11175 -0.01" rpy="0 0 0"></origin>
		<parent link="LEFT_UPPER_ARM"></parent>
		<child link="LEFT_FOREARM"></child>
		<axis xyz="1 0 0"></axis>
	</joint>
	<joint name="RIGHT_SHOULDER_Y" type="revolute">
		<origin xyz="-0.0771 0.05 0.004" rpy="-1.5707963267949 0 0"></origin>
		<parent link="BACK"></parent>
		<child link="RIGHT_CLAVICLE"></child>
		<axis xyz="-1 0 0"></axis>
	</joint>
	<joint name="RIGHT_SHOULDER_X" type="revolute">
		<origin xyz="-0.0284 0 0" rpy="3.14159265358979 0 -1.5707963267949"></origin>
		<parent link="RIGHT_CLAVICLE"></parent>
		<child link="RIGHT_SHOULDER_LINK"></child>
		<axis xyz="0 0 -1"></axis>
	</joint>
	<joint name="RIGHT_ARM_Z" type="revolute">
		<origin xyz="0 0.03625 0.0185" rpy="0 0 0"></origin>
		<parent link="RIGHT_SHOULDER_LINK"></parent>
		<child link="RIGHT_UPPER_ARM"></child>
		<axis xyz="0 1 0"></axis>
	</joint>
	<joint name="RIGHT_ELBOW_Y" type="revolute">
		<origin xyz="0 0.11175 -0.01" rpy="0 0 0"></origin>
		<parent link="RIGHT_UPPER_ARM"></parent>
		<child link="RIGHT_FOREARM"></child>
		<axis xyz="-1 0 0"></axis>
	</joint>
</robot>